[2025-05-05T13:49:40.121+0000] {taskinstance.py:1159} INFO - Dependencies all met for dep_context=non-requeueable deps ti=<TaskInstance: Load_Data.load_csv_to_postgres manual__2025-05-05T13:49:30.628169+00:00 [queued]>
[2025-05-05T13:49:40.159+0000] {taskinstance.py:1159} INFO - Dependencies all met for dep_context=requeueable deps ti=<TaskInstance: Load_Data.load_csv_to_postgres manual__2025-05-05T13:49:30.628169+00:00 [queued]>
[2025-05-05T13:49:40.160+0000] {taskinstance.py:1361} INFO - Starting attempt 1 of 2
[2025-05-05T13:49:40.228+0000] {taskinstance.py:1382} INFO - Executing <Task(PythonOperator): load_csv_to_postgres> on 2025-05-05 13:49:30.628169+00:00
[2025-05-05T13:49:40.259+0000] {standard_task_runner.py:57} INFO - Started process 223 to run task
[2025-05-05T13:49:40.285+0000] {standard_task_runner.py:84} INFO - Running: ['airflow', 'tasks', 'run', 'Load_Data', 'load_csv_to_postgres', 'manual__2025-05-05T13:49:30.628169+00:00', '--job-id', '117', '--raw', '--subdir', 'DAGS_FOLDER/Load_Data.py', '--cfg-path', '/tmp/tmphkhze318']
[2025-05-05T13:49:40.305+0000] {standard_task_runner.py:85} INFO - Job 117: Subtask load_csv_to_postgres
[2025-05-05T13:49:40.528+0000] {task_command.py:416} INFO - Running <TaskInstance: Load_Data.load_csv_to_postgres manual__2025-05-05T13:49:30.628169+00:00 [running]> on host airflow-worker-5c47d7d789-mw9hk
[2025-05-05T13:49:41.680+0000] {taskinstance.py:1662} INFO - Exporting env vars: AIRFLOW_CTX_DAG_OWNER='airflow' AIRFLOW_CTX_DAG_ID='Load_Data' AIRFLOW_CTX_TASK_ID='load_csv_to_postgres' AIRFLOW_CTX_EXECUTION_DATE='2025-05-05T13:49:30.628169+00:00' AIRFLOW_CTX_TRY_NUMBER='1' AIRFLOW_CTX_DAG_RUN_ID='manual__2025-05-05T13:49:30.628169+00:00'
[2025-05-05T13:49:45.217+0000] {taskinstance.py:1937} ERROR - Task failed with exception
Traceback (most recent call last):
  File "/home/airflow/.local/lib/python3.10/site-packages/airflow/operators/python.py", line 192, in execute
    return_value = self.execute_callable()
  File "/home/airflow/.local/lib/python3.10/site-packages/airflow/operators/python.py", line 209, in execute_callable
    return self.python_callable(*self.op_args, **self.op_kwargs)
  File "/opt/airflow/dags/Load_Data.py", line 32, in load_csv_to_postgres
    df_cleaned.to_sql('diabetic_data', engine, index=False, if_exists='append')
NameError: name 'df_cleaned' is not defined
[2025-05-05T13:49:45.306+0000] {taskinstance.py:1400} INFO - Marking task as UP_FOR_RETRY. dag_id=Load_Data, task_id=load_csv_to_postgres, execution_date=20250505T134930, start_date=20250505T134940, end_date=20250505T134945
[2025-05-05T13:49:45.444+0000] {standard_task_runner.py:104} ERROR - Failed to execute job 117 for task load_csv_to_postgres (name 'df_cleaned' is not defined; 223)
[2025-05-05T13:49:45.667+0000] {local_task_job_runner.py:228} INFO - Task exited with return code 1
[2025-05-05T13:49:45.961+0000] {taskinstance.py:2778} INFO - 0 downstream tasks scheduled from follow-on schedule check
