[2025-05-05T13:37:23.875+0000] {taskinstance.py:1159} INFO - Dependencies all met for dep_context=non-requeueable deps ti=<TaskInstance: Load_Data.trigger_preprocess_data manual__2025-05-05T13:37:10.642262+00:00 [queued]>
[2025-05-05T13:37:23.892+0000] {taskinstance.py:1159} INFO - Dependencies all met for dep_context=requeueable deps ti=<TaskInstance: Load_Data.trigger_preprocess_data manual__2025-05-05T13:37:10.642262+00:00 [queued]>
[2025-05-05T13:37:23.892+0000] {taskinstance.py:1361} INFO - Starting attempt 1 of 2
[2025-05-05T13:37:23.913+0000] {taskinstance.py:1382} INFO - Executing <Task(TriggerDagRunOperator): trigger_preprocess_data> on 2025-05-05 13:37:10.642262+00:00
[2025-05-05T13:37:23.939+0000] {standard_task_runner.py:57} INFO - Started process 124 to run task
[2025-05-05T13:37:23.957+0000] {standard_task_runner.py:84} INFO - Running: ['airflow', 'tasks', 'run', 'Load_Data', 'trigger_preprocess_data', 'manual__2025-05-05T13:37:10.642262+00:00', '--job-id', '97', '--raw', '--subdir', 'DAGS_FOLDER/Load_Data.py', '--cfg-path', '/tmp/tmpt7kuvz4l']
[2025-05-05T13:37:23.965+0000] {standard_task_runner.py:85} INFO - Job 97: Subtask trigger_preprocess_data
[2025-05-05T13:37:24.177+0000] {task_command.py:416} INFO - Running <TaskInstance: Load_Data.trigger_preprocess_data manual__2025-05-05T13:37:10.642262+00:00 [running]> on host airflow-worker-5c47d7d789-mw9hk
[2025-05-05T13:37:25.000+0000] {taskinstance.py:1662} INFO - Exporting env vars: AIRFLOW_CTX_DAG_OWNER='airflow' AIRFLOW_CTX_DAG_ID='Load_Data' AIRFLOW_CTX_TASK_ID='trigger_preprocess_data' AIRFLOW_CTX_EXECUTION_DATE='2025-05-05T13:37:10.642262+00:00' AIRFLOW_CTX_TRY_NUMBER='1' AIRFLOW_CTX_DAG_RUN_ID='manual__2025-05-05T13:37:10.642262+00:00'
[2025-05-05T13:37:25.121+0000] {taskinstance.py:1937} ERROR - Task failed with exception
Traceback (most recent call last):
  File "/home/airflow/.local/lib/python3.10/site-packages/airflow/operators/trigger_dagrun.py", line 163, in execute
    dag_run = trigger_dag(
  File "/home/airflow/.local/lib/python3.10/site-packages/airflow/api/common/trigger_dag.py", line 122, in trigger_dag
    triggers = _trigger_dag(
  File "/home/airflow/.local/lib/python3.10/site-packages/airflow/api/common/trigger_dag.py", line 52, in _trigger_dag
    raise DagNotFound(f"Dag id {dag_id} not found")
airflow.exceptions.DagNotFound: Dag id Preprocess_Data not found
[2025-05-05T13:37:25.138+0000] {taskinstance.py:1400} INFO - Marking task as UP_FOR_RETRY. dag_id=Load_Data, task_id=trigger_preprocess_data, execution_date=20250505T133710, start_date=20250505T133723, end_date=20250505T133725
[2025-05-05T13:37:25.167+0000] {standard_task_runner.py:104} ERROR - Failed to execute job 97 for task trigger_preprocess_data (Dag id Preprocess_Data not found; 124)
[2025-05-05T13:37:25.243+0000] {local_task_job_runner.py:228} INFO - Task exited with return code 1
[2025-05-05T13:37:25.305+0000] {taskinstance.py:2778} INFO - 0 downstream tasks scheduled from follow-on schedule check
