[2025-05-05T12:49:07.049+0000] {taskinstance.py:1159} INFO - Dependencies all met for dep_context=non-requeueable deps ti=<TaskInstance: Train_Model.entrenar_modelo manual__2025-05-05T12:48:49.529432+00:00 [queued]>
[2025-05-05T12:49:07.096+0000] {taskinstance.py:1159} INFO - Dependencies all met for dep_context=requeueable deps ti=<TaskInstance: Train_Model.entrenar_modelo manual__2025-05-05T12:48:49.529432+00:00 [queued]>
[2025-05-05T12:49:07.097+0000] {taskinstance.py:1361} INFO - Starting attempt 1 of 2
[2025-05-05T12:49:07.159+0000] {taskinstance.py:1382} INFO - Executing <Task(PythonOperator): entrenar_modelo> on 2025-05-05 12:48:49.529432+00:00
[2025-05-05T12:49:07.226+0000] {standard_task_runner.py:57} INFO - Started process 94 to run task
[2025-05-05T12:49:07.280+0000] {standard_task_runner.py:84} INFO - Running: ['airflow', 'tasks', 'run', 'Train_Model', 'entrenar_modelo', 'manual__2025-05-05T12:48:49.529432+00:00', '--job-id', '45', '--raw', '--subdir', 'DAGS_FOLDER/Train_Data.py', '--cfg-path', '/tmp/tmpptchaeud']
[2025-05-05T12:49:07.333+0000] {standard_task_runner.py:85} INFO - Job 45: Subtask entrenar_modelo
[2025-05-05T12:49:07.722+0000] {task_command.py:416} INFO - Running <TaskInstance: Train_Model.entrenar_modelo manual__2025-05-05T12:48:49.529432+00:00 [running]> on host airflow-worker-74c55458f9-gfj2z
[2025-05-05T12:49:08.418+0000] {taskinstance.py:1662} INFO - Exporting env vars: AIRFLOW_CTX_DAG_OWNER='airflow' AIRFLOW_CTX_DAG_ID='Train_Model' AIRFLOW_CTX_TASK_ID='entrenar_modelo' AIRFLOW_CTX_EXECUTION_DATE='2025-05-05T12:48:49.529432+00:00' AIRFLOW_CTX_TRY_NUMBER='1' AIRFLOW_CTX_DAG_RUN_ID='manual__2025-05-05T12:48:49.529432+00:00'
[2025-05-05T12:49:08.444+0000] {taskinstance.py:1937} ERROR - Task failed with exception
Traceback (most recent call last):
  File "/home/airflow/.local/lib/python3.10/site-packages/airflow/operators/python.py", line 192, in execute
    return_value = self.execute_callable()
  File "/home/airflow/.local/lib/python3.10/site-packages/airflow/operators/python.py", line 209, in execute_callable
    return self.python_callable(*self.op_args, **self.op_kwargs)
  File "/opt/airflow/dags/Train_Data.py", line 28, in entrenar_modelo
    conn = psycopg2.connect(**DB_CONFIG)
  File "/home/airflow/.local/lib/python3.10/site-packages/psycopg2/__init__.py", line 122, in connect
    conn = _connect(dsn, connection_factory=connection_factory, **kwasync)
psycopg2.OperationalError: connection to server at "postgres-mlflow" (10.152.183.205), port 5432 failed: FATAL:  database "data_db" does not exist

[2025-05-05T12:49:08.486+0000] {taskinstance.py:1400} INFO - Marking task as UP_FOR_RETRY. dag_id=Train_Model, task_id=entrenar_modelo, execution_date=20250505T124849, start_date=20250505T124907, end_date=20250505T124908
[2025-05-05T12:49:08.511+0000] {standard_task_runner.py:104} ERROR - Failed to execute job 45 for task entrenar_modelo (connection to server at "postgres-mlflow" (10.152.183.205), port 5432 failed: FATAL:  database "data_db" does not exist
; 94)
[2025-05-05T12:49:08.639+0000] {local_task_job_runner.py:228} INFO - Task exited with return code 1
[2025-05-05T12:49:08.762+0000] {taskinstance.py:2778} INFO - 0 downstream tasks scheduled from follow-on schedule check
