[2025-05-05T13:16:03.677+0000] {taskinstance.py:1159} INFO - Dependencies all met for dep_context=non-requeueable deps ti=<TaskInstance: Load_Data.load_csv_to_postgres manual__2025-05-05T13:10:51.740466+00:00 [queued]>
[2025-05-05T13:16:03.699+0000] {taskinstance.py:1159} INFO - Dependencies all met for dep_context=requeueable deps ti=<TaskInstance: Load_Data.load_csv_to_postgres manual__2025-05-05T13:10:51.740466+00:00 [queued]>
[2025-05-05T13:16:03.700+0000] {taskinstance.py:1361} INFO - Starting attempt 2 of 2
[2025-05-05T13:16:03.732+0000] {taskinstance.py:1382} INFO - Executing <Task(PythonOperator): load_csv_to_postgres> on 2025-05-05 13:10:51.740466+00:00
[2025-05-05T13:16:03.769+0000] {standard_task_runner.py:57} INFO - Started process 256 to run task
[2025-05-05T13:16:03.791+0000] {standard_task_runner.py:84} INFO - Running: ['airflow', 'tasks', 'run', 'Load_Data', 'load_csv_to_postgres', 'manual__2025-05-05T13:10:51.740466+00:00', '--job-id', '74', '--raw', '--subdir', 'DAGS_FOLDER/Load_Data.py', '--cfg-path', '/tmp/tmp4lk2jqbu']
[2025-05-05T13:16:03.803+0000] {standard_task_runner.py:85} INFO - Job 74: Subtask load_csv_to_postgres
[2025-05-05T13:16:03.978+0000] {task_command.py:416} INFO - Running <TaskInstance: Load_Data.load_csv_to_postgres manual__2025-05-05T13:10:51.740466+00:00 [running]> on host airflow-worker-74c55458f9-gfj2z
[2025-05-05T13:16:04.738+0000] {taskinstance.py:1662} INFO - Exporting env vars: AIRFLOW_CTX_DAG_OWNER='airflow' AIRFLOW_CTX_DAG_ID='Load_Data' AIRFLOW_CTX_TASK_ID='load_csv_to_postgres' AIRFLOW_CTX_EXECUTION_DATE='2025-05-05T13:10:51.740466+00:00' AIRFLOW_CTX_TRY_NUMBER='2' AIRFLOW_CTX_DAG_RUN_ID='manual__2025-05-05T13:10:51.740466+00:00'
[2025-05-05T13:16:04.747+0000] {taskinstance.py:1937} ERROR - Task failed with exception
Traceback (most recent call last):
  File "/home/airflow/.local/lib/python3.10/site-packages/airflow/operators/python.py", line 192, in execute
    return_value = self.execute_callable()
  File "/home/airflow/.local/lib/python3.10/site-packages/airflow/operators/python.py", line 209, in execute_callable
    return self.python_callable(*self.op_args, **self.op_kwargs)
  File "/opt/airflow/dags/Load_Data.py", line 19, in load_csv_to_postgres
    df = pd.read_csv(csv_path)
  File "/home/airflow/.local/lib/python3.10/site-packages/pandas/io/parsers/readers.py", line 948, in read_csv
    return _read(filepath_or_buffer, kwds)
  File "/home/airflow/.local/lib/python3.10/site-packages/pandas/io/parsers/readers.py", line 611, in _read
    parser = TextFileReader(filepath_or_buffer, **kwds)
  File "/home/airflow/.local/lib/python3.10/site-packages/pandas/io/parsers/readers.py", line 1448, in __init__
    self._engine = self._make_engine(f, self.engine)
  File "/home/airflow/.local/lib/python3.10/site-packages/pandas/io/parsers/readers.py", line 1705, in _make_engine
    self.handles = get_handle(
  File "/home/airflow/.local/lib/python3.10/site-packages/pandas/io/common.py", line 863, in get_handle
    handle = open(
FileNotFoundError: [Errno 2] No such file or directory: '/opt/airflow/data/diabetic_data.csv'
[2025-05-05T13:16:04.796+0000] {taskinstance.py:1400} INFO - Marking task as FAILED. dag_id=Load_Data, task_id=load_csv_to_postgres, execution_date=20250505T131051, start_date=20250505T131603, end_date=20250505T131604
[2025-05-05T13:16:04.829+0000] {standard_task_runner.py:104} ERROR - Failed to execute job 74 for task load_csv_to_postgres ([Errno 2] No such file or directory: '/opt/airflow/data/diabetic_data.csv'; 256)
[2025-05-05T13:16:04.944+0000] {local_task_job_runner.py:228} INFO - Task exited with return code 1
[2025-05-05T13:16:05.068+0000] {taskinstance.py:2778} INFO - 0 downstream tasks scheduled from follow-on schedule check
