[2025-05-05T02:47:17.330+0000] {taskinstance.py:1159} INFO - Dependencies all met for dep_context=non-requeueable deps ti=<TaskInstance: Load_Data.download_dataset manual__2025-05-05T02:47:08.133939+00:00 [queued]>
[2025-05-05T02:47:17.355+0000] {taskinstance.py:1159} INFO - Dependencies all met for dep_context=requeueable deps ti=<TaskInstance: Load_Data.download_dataset manual__2025-05-05T02:47:08.133939+00:00 [queued]>
[2025-05-05T02:47:17.355+0000] {taskinstance.py:1361} INFO - Starting attempt 1 of 2
[2025-05-05T02:47:17.415+0000] {taskinstance.py:1382} INFO - Executing <Task(PythonOperator): download_dataset> on 2025-05-05 02:47:08.133939+00:00
[2025-05-05T02:47:17.464+0000] {standard_task_runner.py:57} INFO - Started process 93 to run task
[2025-05-05T02:47:17.479+0000] {standard_task_runner.py:84} INFO - Running: ['airflow', 'tasks', 'run', 'Load_Data', 'download_dataset', 'manual__2025-05-05T02:47:08.133939+00:00', '--job-id', '30', '--raw', '--subdir', 'DAGS_FOLDER/Load_Data.py', '--cfg-path', '/tmp/tmp9_8a_lw2']
[2025-05-05T02:47:17.493+0000] {standard_task_runner.py:85} INFO - Job 30: Subtask download_dataset
[2025-05-05T02:47:17.679+0000] {task_command.py:416} INFO - Running <TaskInstance: Load_Data.download_dataset manual__2025-05-05T02:47:08.133939+00:00 [running]> on host airflow-worker-79b6d7f9f-dvv8h
[2025-05-05T02:47:17.993+0000] {taskinstance.py:1662} INFO - Exporting env vars: AIRFLOW_CTX_DAG_OWNER='airflow' AIRFLOW_CTX_DAG_ID='Load_Data' AIRFLOW_CTX_TASK_ID='download_dataset' AIRFLOW_CTX_EXECUTION_DATE='2025-05-05T02:47:08.133939+00:00' AIRFLOW_CTX_TRY_NUMBER='1' AIRFLOW_CTX_DAG_RUN_ID='manual__2025-05-05T02:47:08.133939+00:00'
[2025-05-05T02:47:20.044+0000] {taskinstance.py:1937} ERROR - Task failed with exception
Traceback (most recent call last):
  File "/home/airflow/.local/lib/python3.10/site-packages/airflow/operators/python.py", line 192, in execute
    return_value = self.execute_callable()
  File "/home/airflow/.local/lib/python3.10/site-packages/airflow/operators/python.py", line 209, in execute_callable
    return self.python_callable(*self.op_args, **self.op_kwargs)
  File "/opt/airflow/dags/Load_Data.py", line 44, in download_if_needed
    resp.raise_for_status()
  File "/home/airflow/.local/lib/python3.10/site-packages/requests/models.py", line 1021, in raise_for_status
    raise HTTPError(http_error_msg, response=self)
requests.exceptions.HTTPError: 404 Client Error: Not Found for url: https://archive.ics.uci.edu/static/public/296/diabetic_data.csv
[2025-05-05T02:47:20.095+0000] {taskinstance.py:1400} INFO - Marking task as UP_FOR_RETRY. dag_id=Load_Data, task_id=download_dataset, execution_date=20250505T024708, start_date=20250505T024717, end_date=20250505T024720
[2025-05-05T02:47:20.124+0000] {standard_task_runner.py:104} ERROR - Failed to execute job 30 for task download_dataset (404 Client Error: Not Found for url: https://archive.ics.uci.edu/static/public/296/diabetic_data.csv; 93)
[2025-05-05T02:47:20.201+0000] {local_task_job_runner.py:228} INFO - Task exited with return code 1
[2025-05-05T02:47:20.290+0000] {taskinstance.py:2778} INFO - 0 downstream tasks scheduled from follow-on schedule check
