[2025-05-05T11:50:05.518+0000] {taskinstance.py:1159} INFO - Dependencies all met for dep_context=non-requeueable deps ti=<TaskInstance: Load_Data.download_dataset manual__2025-05-05T11:49:58.273464+00:00 [queued]>
[2025-05-05T11:50:05.535+0000] {taskinstance.py:1159} INFO - Dependencies all met for dep_context=requeueable deps ti=<TaskInstance: Load_Data.download_dataset manual__2025-05-05T11:49:58.273464+00:00 [queued]>
[2025-05-05T11:50:05.535+0000] {taskinstance.py:1361} INFO - Starting attempt 1 of 2
[2025-05-05T11:50:05.576+0000] {taskinstance.py:1382} INFO - Executing <Task(PythonOperator): download_dataset> on 2025-05-05 11:49:58.273464+00:00
[2025-05-05T11:50:05.611+0000] {standard_task_runner.py:57} INFO - Started process 123 to run task
[2025-05-05T11:50:05.641+0000] {standard_task_runner.py:84} INFO - Running: ['airflow', 'tasks', 'run', 'Load_Data', 'download_dataset', 'manual__2025-05-05T11:49:58.273464+00:00', '--job-id', '34', '--raw', '--subdir', 'DAGS_FOLDER/Load_Data.py', '--cfg-path', '/tmp/tmpxz5b3yn1']
[2025-05-05T11:50:05.651+0000] {standard_task_runner.py:85} INFO - Job 34: Subtask download_dataset
[2025-05-05T11:50:06.048+0000] {task_command.py:416} INFO - Running <TaskInstance: Load_Data.download_dataset manual__2025-05-05T11:49:58.273464+00:00 [running]> on host airflow-worker-79b6d7f9f-dvv8h
[2025-05-05T11:50:06.253+0000] {taskinstance.py:1662} INFO - Exporting env vars: AIRFLOW_CTX_DAG_OWNER='airflow' AIRFLOW_CTX_DAG_ID='Load_Data' AIRFLOW_CTX_TASK_ID='download_dataset' AIRFLOW_CTX_EXECUTION_DATE='2025-05-05T11:49:58.273464+00:00' AIRFLOW_CTX_TRY_NUMBER='1' AIRFLOW_CTX_DAG_RUN_ID='manual__2025-05-05T11:49:58.273464+00:00'
[2025-05-05T11:50:25.764+0000] {taskinstance.py:1937} ERROR - Task failed with exception
Traceback (most recent call last):
  File "/home/airflow/.local/lib/python3.10/site-packages/urllib3/connectionpool.py", line 715, in urlopen
    httplib_response = self._make_request(
  File "/home/airflow/.local/lib/python3.10/site-packages/urllib3/connectionpool.py", line 416, in _make_request
    conn.request(method, url, **httplib_request_kw)
  File "/home/airflow/.local/lib/python3.10/site-packages/botocore/awsrequest.py", line 96, in request
    rval = super().request(method, url, body, headers, *args, **kwargs)
  File "/home/airflow/.local/lib/python3.10/site-packages/urllib3/connection.py", line 244, in request
    super(HTTPConnection, self).request(method, url, body=body, headers=headers)
  File "/usr/local/lib/python3.10/http/client.py", line 1283, in request
    self._send_request(method, url, body, headers, encode_chunked)
  File "/usr/local/lib/python3.10/http/client.py", line 1329, in _send_request
    self.endheaders(body, encode_chunked=encode_chunked)
  File "/usr/local/lib/python3.10/http/client.py", line 1278, in endheaders
    self._send_output(message_body, encode_chunked=encode_chunked)
  File "/home/airflow/.local/lib/python3.10/site-packages/botocore/awsrequest.py", line 130, in _send_output
    self._handle_expect_response(message_body)
  File "/home/airflow/.local/lib/python3.10/site-packages/botocore/awsrequest.py", line 176, in _handle_expect_response
    self._send_message_body(message_body)
  File "/home/airflow/.local/lib/python3.10/site-packages/botocore/awsrequest.py", line 209, in _send_message_body
    self.send(message_body)
  File "/home/airflow/.local/lib/python3.10/site-packages/botocore/awsrequest.py", line 223, in send
    return super().send(str)
  File "/usr/local/lib/python3.10/http/client.py", line 995, in send
    self.sock.sendall(datablock)
ConnectionResetError: [Errno 104] Connection reset by peer

During handling of the above exception, another exception occurred:

Traceback (most recent call last):
  File "/home/airflow/.local/lib/python3.10/site-packages/botocore/httpsession.py", line 464, in send
    urllib_response = conn.urlopen(
  File "/home/airflow/.local/lib/python3.10/site-packages/urllib3/connectionpool.py", line 799, in urlopen
    retries = retries.increment(
  File "/home/airflow/.local/lib/python3.10/site-packages/urllib3/util/retry.py", line 525, in increment
    raise six.reraise(type(error), error, _stacktrace)
  File "/home/airflow/.local/lib/python3.10/site-packages/urllib3/packages/six.py", line 769, in reraise
    raise value.with_traceback(tb)
  File "/home/airflow/.local/lib/python3.10/site-packages/urllib3/connectionpool.py", line 715, in urlopen
    httplib_response = self._make_request(
  File "/home/airflow/.local/lib/python3.10/site-packages/urllib3/connectionpool.py", line 416, in _make_request
    conn.request(method, url, **httplib_request_kw)
  File "/home/airflow/.local/lib/python3.10/site-packages/botocore/awsrequest.py", line 96, in request
    rval = super().request(method, url, body, headers, *args, **kwargs)
  File "/home/airflow/.local/lib/python3.10/site-packages/urllib3/connection.py", line 244, in request
    super(HTTPConnection, self).request(method, url, body=body, headers=headers)
  File "/usr/local/lib/python3.10/http/client.py", line 1283, in request
    self._send_request(method, url, body, headers, encode_chunked)
  File "/usr/local/lib/python3.10/http/client.py", line 1329, in _send_request
    self.endheaders(body, encode_chunked=encode_chunked)
  File "/usr/local/lib/python3.10/http/client.py", line 1278, in endheaders
    self._send_output(message_body, encode_chunked=encode_chunked)
  File "/home/airflow/.local/lib/python3.10/site-packages/botocore/awsrequest.py", line 130, in _send_output
    self._handle_expect_response(message_body)
  File "/home/airflow/.local/lib/python3.10/site-packages/botocore/awsrequest.py", line 176, in _handle_expect_response
    self._send_message_body(message_body)
  File "/home/airflow/.local/lib/python3.10/site-packages/botocore/awsrequest.py", line 209, in _send_message_body
    self.send(message_body)
  File "/home/airflow/.local/lib/python3.10/site-packages/botocore/awsrequest.py", line 223, in send
    return super().send(str)
  File "/usr/local/lib/python3.10/http/client.py", line 995, in send
    self.sock.sendall(datablock)
urllib3.exceptions.ProtocolError: ('Connection aborted.', ConnectionResetError(104, 'Connection reset by peer'))

During handling of the above exception, another exception occurred:

Traceback (most recent call last):
  File "/home/airflow/.local/lib/python3.10/site-packages/airflow/operators/python.py", line 192, in execute
    return_value = self.execute_callable()
  File "/home/airflow/.local/lib/python3.10/site-packages/airflow/operators/python.py", line 209, in execute_callable
    return self.python_callable(*self.op_args, **self.op_kwargs)
  File "/opt/airflow/dags/Load_Data.py", line 45, in download_if_needed
    _s3().put_object(Bucket=BKT, Key=CSV_OBJ, Body=resp.content)
  File "/home/airflow/.local/lib/python3.10/site-packages/botocore/client.py", line 535, in _api_call
    return self._make_api_call(operation_name, kwargs)
  File "/home/airflow/.local/lib/python3.10/site-packages/botocore/client.py", line 963, in _make_api_call
    http, parsed_response = self._make_request(
  File "/home/airflow/.local/lib/python3.10/site-packages/botocore/client.py", line 986, in _make_request
    return self._endpoint.make_request(operation_model, request_dict)
  File "/home/airflow/.local/lib/python3.10/site-packages/botocore/endpoint.py", line 119, in make_request
    return self._send_request(request_dict, operation_model)
  File "/home/airflow/.local/lib/python3.10/site-packages/botocore/endpoint.py", line 202, in _send_request
    while self._needs_retry(
  File "/home/airflow/.local/lib/python3.10/site-packages/botocore/endpoint.py", line 354, in _needs_retry
    responses = self._event_emitter.emit(
  File "/home/airflow/.local/lib/python3.10/site-packages/botocore/hooks.py", line 412, in emit
    return self._emitter.emit(aliased_event_name, **kwargs)
  File "/home/airflow/.local/lib/python3.10/site-packages/botocore/hooks.py", line 256, in emit
    return self._emit(event_name, kwargs)
  File "/home/airflow/.local/lib/python3.10/site-packages/botocore/hooks.py", line 239, in _emit
    response = handler(**kwargs)
  File "/home/airflow/.local/lib/python3.10/site-packages/botocore/retryhandler.py", line 207, in __call__
    if self._checker(**checker_kwargs):
  File "/home/airflow/.local/lib/python3.10/site-packages/botocore/retryhandler.py", line 284, in __call__
    should_retry = self._should_retry(
  File "/home/airflow/.local/lib/python3.10/site-packages/botocore/retryhandler.py", line 320, in _should_retry
    return self._checker(attempt_number, response, caught_exception)
  File "/home/airflow/.local/lib/python3.10/site-packages/botocore/retryhandler.py", line 363, in __call__
    checker_response = checker(
  File "/home/airflow/.local/lib/python3.10/site-packages/botocore/retryhandler.py", line 247, in __call__
    return self._check_caught_exception(
  File "/home/airflow/.local/lib/python3.10/site-packages/botocore/retryhandler.py", line 416, in _check_caught_exception
    raise caught_exception
  File "/home/airflow/.local/lib/python3.10/site-packages/botocore/endpoint.py", line 281, in _do_get_response
    http_response = self._send(request)
  File "/home/airflow/.local/lib/python3.10/site-packages/botocore/endpoint.py", line 377, in _send
    return self.http_session.send(request)
  File "/home/airflow/.local/lib/python3.10/site-packages/botocore/httpsession.py", line 503, in send
    raise ConnectionClosedError(
botocore.exceptions.ConnectionClosedError: Connection was closed before we received a valid response from endpoint URL: "http://minio:9000/datasets/diabetic_data.csv".
[2025-05-05T11:50:26.057+0000] {taskinstance.py:1400} INFO - Marking task as UP_FOR_RETRY. dag_id=Load_Data, task_id=download_dataset, execution_date=20250505T114958, start_date=20250505T115005, end_date=20250505T115026
[2025-05-05T11:50:26.187+0000] {standard_task_runner.py:104} ERROR - Failed to execute job 34 for task download_dataset (Connection was closed before we received a valid response from endpoint URL: "http://minio:9000/datasets/diabetic_data.csv".; 123)
[2025-05-05T11:50:26.368+0000] {local_task_job_runner.py:228} INFO - Task exited with return code 1
[2025-05-05T11:50:26.490+0000] {taskinstance.py:2778} INFO - 0 downstream tasks scheduled from follow-on schedule check
