[2025-05-05T12:46:46.701+0000] {taskinstance.py:1159} INFO - Dependencies all met for dep_context=non-requeueable deps ti=<TaskInstance: Preprocess_Data.trigger_train_dag manual__2025-05-05T12:46:31.194694+00:00 [queued]>
[2025-05-05T12:46:46.749+0000] {taskinstance.py:1159} INFO - Dependencies all met for dep_context=requeueable deps ti=<TaskInstance: Preprocess_Data.trigger_train_dag manual__2025-05-05T12:46:31.194694+00:00 [queued]>
[2025-05-05T12:46:46.750+0000] {taskinstance.py:1361} INFO - Starting attempt 1 of 2
[2025-05-05T12:46:46.800+0000] {taskinstance.py:1382} INFO - Executing <Task(TriggerDagRunOperator): trigger_train_dag> on 2025-05-05 12:46:31.194694+00:00
[2025-05-05T12:46:46.817+0000] {standard_task_runner.py:57} INFO - Started process 79 to run task
[2025-05-05T12:46:46.843+0000] {standard_task_runner.py:84} INFO - Running: ['airflow', 'tasks', 'run', 'Preprocess_Data', 'trigger_train_dag', 'manual__2025-05-05T12:46:31.194694+00:00', '--job-id', '42', '--raw', '--subdir', 'DAGS_FOLDER/Preprocess_Data.py', '--cfg-path', '/tmp/tmpzl25w_er']
[2025-05-05T12:46:46.858+0000] {standard_task_runner.py:85} INFO - Job 42: Subtask trigger_train_dag
[2025-05-05T12:46:47.132+0000] {task_command.py:416} INFO - Running <TaskInstance: Preprocess_Data.trigger_train_dag manual__2025-05-05T12:46:31.194694+00:00 [running]> on host airflow-worker-74c55458f9-gfj2z
[2025-05-05T12:46:47.969+0000] {taskinstance.py:1662} INFO - Exporting env vars: AIRFLOW_CTX_DAG_OWNER='airflow' AIRFLOW_CTX_DAG_ID='Preprocess_Data' AIRFLOW_CTX_TASK_ID='trigger_train_dag' AIRFLOW_CTX_EXECUTION_DATE='2025-05-05T12:46:31.194694+00:00' AIRFLOW_CTX_TRY_NUMBER='1' AIRFLOW_CTX_DAG_RUN_ID='manual__2025-05-05T12:46:31.194694+00:00'
[2025-05-05T12:46:48.051+0000] {taskinstance.py:1937} ERROR - Task failed with exception
Traceback (most recent call last):
  File "/home/airflow/.local/lib/python3.10/site-packages/airflow/operators/trigger_dagrun.py", line 163, in execute
    dag_run = trigger_dag(
  File "/home/airflow/.local/lib/python3.10/site-packages/airflow/api/common/trigger_dag.py", line 119, in trigger_dag
    raise DagNotFound(f"Dag id {dag_id} not found in DagModel")
airflow.exceptions.DagNotFound: Dag id Train_Data not found in DagModel
[2025-05-05T12:46:48.068+0000] {taskinstance.py:1400} INFO - Marking task as UP_FOR_RETRY. dag_id=Preprocess_Data, task_id=trigger_train_dag, execution_date=20250505T124631, start_date=20250505T124646, end_date=20250505T124648
[2025-05-05T12:46:48.093+0000] {standard_task_runner.py:104} ERROR - Failed to execute job 42 for task trigger_train_dag (Dag id Train_Data not found in DagModel; 79)
[2025-05-05T12:46:48.170+0000] {local_task_job_runner.py:228} INFO - Task exited with return code 1
[2025-05-05T12:46:48.242+0000] {taskinstance.py:2778} INFO - 0 downstream tasks scheduled from follow-on schedule check
