[2025-05-05T02:37:12.901+0000] {taskinstance.py:1159} INFO - Dependencies all met for dep_context=non-requeueable deps ti=<TaskInstance: Mlflow_Configuration.configurar_mlflow manual__2025-05-05T02:36:54.949717+00:00 [queued]>
[2025-05-05T02:37:12.938+0000] {taskinstance.py:1159} INFO - Dependencies all met for dep_context=requeueable deps ti=<TaskInstance: Mlflow_Configuration.configurar_mlflow manual__2025-05-05T02:36:54.949717+00:00 [queued]>
[2025-05-05T02:37:12.938+0000] {taskinstance.py:1361} INFO - Starting attempt 1 of 2
[2025-05-05T02:37:12.980+0000] {taskinstance.py:1382} INFO - Executing <Task(PythonOperator): configurar_mlflow> on 2025-05-05 02:36:54.949717+00:00
[2025-05-05T02:37:13.021+0000] {standard_task_runner.py:57} INFO - Started process 65 to run task
[2025-05-05T02:37:13.052+0000] {standard_task_runner.py:84} INFO - Running: ['airflow', 'tasks', 'run', 'Mlflow_Configuration', 'configurar_mlflow', 'manual__2025-05-05T02:36:54.949717+00:00', '--job-id', '24', '--raw', '--subdir', 'DAGS_FOLDER/Config_MLFlow.py', '--cfg-path', '/tmp/tmps024zyql']
[2025-05-05T02:37:13.074+0000] {standard_task_runner.py:85} INFO - Job 24: Subtask configurar_mlflow
[2025-05-05T02:37:13.323+0000] {task_command.py:416} INFO - Running <TaskInstance: Mlflow_Configuration.configurar_mlflow manual__2025-05-05T02:36:54.949717+00:00 [running]> on host airflow-worker-79b6d7f9f-dvv8h
[2025-05-05T02:37:14.560+0000] {taskinstance.py:1662} INFO - Exporting env vars: AIRFLOW_CTX_DAG_OWNER='airflow' AIRFLOW_CTX_DAG_ID='Mlflow_Configuration' AIRFLOW_CTX_TASK_ID='configurar_mlflow' AIRFLOW_CTX_EXECUTION_DATE='2025-05-05T02:36:54.949717+00:00' AIRFLOW_CTX_TRY_NUMBER='1' AIRFLOW_CTX_DAG_RUN_ID='manual__2025-05-05T02:36:54.949717+00:00'
[2025-05-05T02:37:14.703+0000] {connectionpool.py:824} WARNING - Retrying (JitteredRetry(total=6, connect=6, read=7, redirect=7, status=7)) after connection broken by 'NewConnectionError('<urllib3.connection.HTTPConnection object at 0x719511697b80>: Failed to establish a new connection: [Errno 111] Connection refused')': /api/2.0/mlflow/experiments/get-by-name?experiment_name=Proyecto_3_Diabetes_Readmission
[2025-05-05T02:37:18.714+0000] {connectionpool.py:824} WARNING - Retrying (JitteredRetry(total=5, connect=5, read=7, redirect=7, status=7)) after connection broken by 'NewConnectionError('<urllib3.connection.HTTPConnection object at 0x719511694d90>: Failed to establish a new connection: [Errno 111] Connection refused')': /api/2.0/mlflow/experiments/get-by-name?experiment_name=Proyecto_3_Diabetes_Readmission
[2025-05-05T02:37:26.728+0000] {connectionpool.py:824} WARNING - Retrying (JitteredRetry(total=4, connect=4, read=7, redirect=7, status=7)) after connection broken by 'NewConnectionError('<urllib3.connection.HTTPConnection object at 0x719511697280>: Failed to establish a new connection: [Errno 111] Connection refused')': /api/2.0/mlflow/experiments/get-by-name?experiment_name=Proyecto_3_Diabetes_Readmission
[2025-05-05T02:37:42.747+0000] {connectionpool.py:824} WARNING - Retrying (JitteredRetry(total=3, connect=3, read=7, redirect=7, status=7)) after connection broken by 'NewConnectionError('<urllib3.connection.HTTPConnection object at 0x719511695000>: Failed to establish a new connection: [Errno 111] Connection refused')': /api/2.0/mlflow/experiments/get-by-name?experiment_name=Proyecto_3_Diabetes_Readmission
[2025-05-05T02:38:14.781+0000] {connectionpool.py:824} WARNING - Retrying (JitteredRetry(total=2, connect=2, read=7, redirect=7, status=7)) after connection broken by 'NewConnectionError('<urllib3.connection.HTTPConnection object at 0x719511695fc0>: Failed to establish a new connection: [Errno 111] Connection refused')': /api/2.0/mlflow/experiments/get-by-name?experiment_name=Proyecto_3_Diabetes_Readmission
[2025-05-05T02:39:18.848+0000] {connectionpool.py:824} WARNING - Retrying (JitteredRetry(total=1, connect=1, read=7, redirect=7, status=7)) after connection broken by 'NewConnectionError('<urllib3.connection.HTTPConnection object at 0x719511694520>: Failed to establish a new connection: [Errno 111] Connection refused')': /api/2.0/mlflow/experiments/get-by-name?experiment_name=Proyecto_3_Diabetes_Readmission
[2025-05-05T02:41:19.009+0000] {connectionpool.py:824} WARNING - Retrying (JitteredRetry(total=0, connect=0, read=7, redirect=7, status=7)) after connection broken by 'NewConnectionError('<urllib3.connection.HTTPConnection object at 0x7195116970a0>: Failed to establish a new connection: [Errno 111] Connection refused')': /api/2.0/mlflow/experiments/get-by-name?experiment_name=Proyecto_3_Diabetes_Readmission
[2025-05-05T02:41:19.023+0000] {logging_mixin.py:154} INFO - Error en la configuraci√≥n de MLflow: API request to http://localhost:30830/api/2.0/mlflow/experiments/get-by-name failed with exception HTTPConnectionPool(host='localhost', port=30830): Max retries exceeded with url: /api/2.0/mlflow/experiments/get-by-name?experiment_name=Proyecto_3_Diabetes_Readmission (Caused by NewConnectionError('<urllib3.connection.HTTPConnection object at 0x719511694730>: Failed to establish a new connection: [Errno 111] Connection refused'))
[2025-05-05T02:41:19.025+0000] {taskinstance.py:1937} ERROR - Task failed with exception
Traceback (most recent call last):
  File "/home/airflow/.local/lib/python3.10/site-packages/urllib3/connection.py", line 174, in _new_conn
    conn = connection.create_connection(
  File "/home/airflow/.local/lib/python3.10/site-packages/urllib3/util/connection.py", line 95, in create_connection
    raise err
  File "/home/airflow/.local/lib/python3.10/site-packages/urllib3/util/connection.py", line 85, in create_connection
    sock.connect(sa)
ConnectionRefusedError: [Errno 111] Connection refused

During handling of the above exception, another exception occurred:

Traceback (most recent call last):
  File "/home/airflow/.local/lib/python3.10/site-packages/urllib3/connectionpool.py", line 715, in urlopen
    httplib_response = self._make_request(
  File "/home/airflow/.local/lib/python3.10/site-packages/urllib3/connectionpool.py", line 416, in _make_request
    conn.request(method, url, **httplib_request_kw)
  File "/home/airflow/.local/lib/python3.10/site-packages/urllib3/connection.py", line 244, in request
    super(HTTPConnection, self).request(method, url, body=body, headers=headers)
  File "/usr/local/lib/python3.10/http/client.py", line 1283, in request
    self._send_request(method, url, body, headers, encode_chunked)
  File "/usr/local/lib/python3.10/http/client.py", line 1329, in _send_request
    self.endheaders(body, encode_chunked=encode_chunked)
  File "/usr/local/lib/python3.10/http/client.py", line 1278, in endheaders
    self._send_output(message_body, encode_chunked=encode_chunked)
  File "/usr/local/lib/python3.10/http/client.py", line 1038, in _send_output
    self.send(msg)
  File "/usr/local/lib/python3.10/http/client.py", line 976, in send
    self.connect()
  File "/home/airflow/.local/lib/python3.10/site-packages/urllib3/connection.py", line 205, in connect
    conn = self._new_conn()
  File "/home/airflow/.local/lib/python3.10/site-packages/urllib3/connection.py", line 186, in _new_conn
    raise NewConnectionError(
urllib3.exceptions.NewConnectionError: <urllib3.connection.HTTPConnection object at 0x719511694730>: Failed to establish a new connection: [Errno 111] Connection refused

During handling of the above exception, another exception occurred:

Traceback (most recent call last):
  File "/home/airflow/.local/lib/python3.10/site-packages/requests/adapters.py", line 486, in send
    resp = conn.urlopen(
  File "/home/airflow/.local/lib/python3.10/site-packages/urllib3/connectionpool.py", line 827, in urlopen
    return self.urlopen(
  File "/home/airflow/.local/lib/python3.10/site-packages/urllib3/connectionpool.py", line 827, in urlopen
    return self.urlopen(
  File "/home/airflow/.local/lib/python3.10/site-packages/urllib3/connectionpool.py", line 827, in urlopen
    return self.urlopen(
  [Previous line repeated 4 more times]
  File "/home/airflow/.local/lib/python3.10/site-packages/urllib3/connectionpool.py", line 799, in urlopen
    retries = retries.increment(
  File "/home/airflow/.local/lib/python3.10/site-packages/urllib3/util/retry.py", line 592, in increment
    raise MaxRetryError(_pool, url, error or ResponseError(cause))
urllib3.exceptions.MaxRetryError: HTTPConnectionPool(host='localhost', port=30830): Max retries exceeded with url: /api/2.0/mlflow/experiments/get-by-name?experiment_name=Proyecto_3_Diabetes_Readmission (Caused by NewConnectionError('<urllib3.connection.HTTPConnection object at 0x719511694730>: Failed to establish a new connection: [Errno 111] Connection refused'))

During handling of the above exception, another exception occurred:

Traceback (most recent call last):
  File "/home/airflow/.local/lib/python3.10/site-packages/mlflow/utils/rest_utils.py", line 184, in http_request
    return _get_http_response_with_retries(
  File "/home/airflow/.local/lib/python3.10/site-packages/mlflow/utils/request_utils.py", line 237, in _get_http_response_with_retries
    return session.request(method, url, allow_redirects=allow_redirects, **kwargs)
  File "/home/airflow/.local/lib/python3.10/site-packages/requests/sessions.py", line 589, in request
    resp = self.send(prep, **send_kwargs)
  File "/home/airflow/.local/lib/python3.10/site-packages/requests/sessions.py", line 703, in send
    r = adapter.send(request, **kwargs)
  File "/home/airflow/.local/lib/python3.10/site-packages/requests/adapters.py", line 519, in send
    raise ConnectionError(e, request=request)
requests.exceptions.ConnectionError: HTTPConnectionPool(host='localhost', port=30830): Max retries exceeded with url: /api/2.0/mlflow/experiments/get-by-name?experiment_name=Proyecto_3_Diabetes_Readmission (Caused by NewConnectionError('<urllib3.connection.HTTPConnection object at 0x719511694730>: Failed to establish a new connection: [Errno 111] Connection refused'))

During handling of the above exception, another exception occurred:

Traceback (most recent call last):
  File "/home/airflow/.local/lib/python3.10/site-packages/airflow/operators/python.py", line 192, in execute
    return_value = self.execute_callable()
  File "/home/airflow/.local/lib/python3.10/site-packages/airflow/operators/python.py", line 209, in execute_callable
    return self.python_callable(*self.op_args, **self.op_kwargs)
  File "/opt/airflow/dags/Config_MLFlow.py", line 26, in configurar_mlflow
    mlflow.set_experiment("Proyecto_3_Diabetes_Readmission")
  File "/home/airflow/.local/lib/python3.10/site-packages/mlflow/tracking/fluent.py", line 157, in set_experiment
    experiment = client.get_experiment_by_name(experiment_name)
  File "/home/airflow/.local/lib/python3.10/site-packages/mlflow/tracking/client.py", line 1703, in get_experiment_by_name
    return self._tracking_client.get_experiment_by_name(name)
  File "/home/airflow/.local/lib/python3.10/site-packages/mlflow/tracking/_tracking_service/client.py", line 591, in get_experiment_by_name
    return self.store.get_experiment_by_name(name)
  File "/home/airflow/.local/lib/python3.10/site-packages/mlflow/store/tracking/rest_store.py", line 641, in get_experiment_by_name
    response_proto = self._call_endpoint(GetExperimentByName, req_body)
  File "/home/airflow/.local/lib/python3.10/site-packages/mlflow/store/tracking/rest_store.py", line 90, in _call_endpoint
    return call_endpoint(self.get_host_creds(), endpoint, method, json_body, response_proto)
  File "/home/airflow/.local/lib/python3.10/site-packages/mlflow/utils/rest_utils.py", line 397, in call_endpoint
    response = http_request(**call_kwargs)
  File "/home/airflow/.local/lib/python3.10/site-packages/mlflow/utils/rest_utils.py", line 207, in http_request
    raise MlflowException(f"API request to {url} failed with exception {e}")
mlflow.exceptions.MlflowException: API request to http://localhost:30830/api/2.0/mlflow/experiments/get-by-name failed with exception HTTPConnectionPool(host='localhost', port=30830): Max retries exceeded with url: /api/2.0/mlflow/experiments/get-by-name?experiment_name=Proyecto_3_Diabetes_Readmission (Caused by NewConnectionError('<urllib3.connection.HTTPConnection object at 0x719511694730>: Failed to establish a new connection: [Errno 111] Connection refused'))
[2025-05-05T02:41:19.223+0000] {taskinstance.py:1400} INFO - Marking task as UP_FOR_RETRY. dag_id=Mlflow_Configuration, task_id=configurar_mlflow, execution_date=20250505T023654, start_date=20250505T023712, end_date=20250505T024119
[2025-05-05T02:41:19.274+0000] {standard_task_runner.py:104} ERROR - Failed to execute job 24 for task configurar_mlflow (API request to http://localhost:30830/api/2.0/mlflow/experiments/get-by-name failed with exception HTTPConnectionPool(host='localhost', port=30830): Max retries exceeded with url: /api/2.0/mlflow/experiments/get-by-name?experiment_name=Proyecto_3_Diabetes_Readmission (Caused by NewConnectionError('<urllib3.connection.HTTPConnection object at 0x719511694730>: Failed to establish a new connection: [Errno 111] Connection refused')); 65)
[2025-05-05T02:41:19.388+0000] {local_task_job_runner.py:228} INFO - Task exited with return code 1
[2025-05-05T02:41:19.466+0000] {taskinstance.py:2778} INFO - 0 downstream tasks scheduled from follow-on schedule check
