[2025-05-05T13:37:03.354+0000] {taskinstance.py:1159} INFO - Dependencies all met for dep_context=non-requeueable deps ti=<TaskInstance: Train_Model.entrenar_modelo manual__2025-05-05T13:31:34.432583+00:00 [queued]>
[2025-05-05T13:37:03.646+0000] {taskinstance.py:1159} INFO - Dependencies all met for dep_context=requeueable deps ti=<TaskInstance: Train_Model.entrenar_modelo manual__2025-05-05T13:31:34.432583+00:00 [queued]>
[2025-05-05T13:37:03.646+0000] {taskinstance.py:1361} INFO - Starting attempt 2 of 2
[2025-05-05T13:37:04.031+0000] {taskinstance.py:1382} INFO - Executing <Task(PythonOperator): entrenar_modelo> on 2025-05-05 13:31:34.432583+00:00
[2025-05-05T13:37:04.327+0000] {standard_task_runner.py:57} INFO - Started process 114 to run task
[2025-05-05T13:37:04.436+0000] {standard_task_runner.py:84} INFO - Running: ['airflow', 'tasks', 'run', 'Train_Model', 'entrenar_modelo', 'manual__2025-05-05T13:31:34.432583+00:00', '--job-id', '93', '--raw', '--subdir', 'DAGS_FOLDER/Train_Data.py', '--cfg-path', '/tmp/tmpy2wj9pp3']
[2025-05-05T13:37:04.467+0000] {standard_task_runner.py:85} INFO - Job 93: Subtask entrenar_modelo
[2025-05-05T13:37:05.051+0000] {task_command.py:416} INFO - Running <TaskInstance: Train_Model.entrenar_modelo manual__2025-05-05T13:31:34.432583+00:00 [running]> on host airflow-worker-5c47d7d789-mw9hk
[2025-05-05T13:37:05.724+0000] {taskinstance.py:1662} INFO - Exporting env vars: AIRFLOW_CTX_DAG_OWNER='airflow' AIRFLOW_CTX_DAG_ID='Train_Model' AIRFLOW_CTX_TASK_ID='entrenar_modelo' AIRFLOW_CTX_EXECUTION_DATE='2025-05-05T13:31:34.432583+00:00' AIRFLOW_CTX_TRY_NUMBER='2' AIRFLOW_CTX_DAG_RUN_ID='manual__2025-05-05T13:31:34.432583+00:00'
[2025-05-05T13:37:05.926+0000] {warnings.py:109} WARNING - /opt/airflow/dags/Train_Data.py:30: UserWarning: pandas only supports SQLAlchemy connectable (engine/connection) or database string URI or sqlite3 DBAPI2 connection. Other DBAPI2 objects are not tested. Please consider using SQLAlchemy.
  df = pd.read_sql("SELECT * FROM diabetic_data_clean", conn)

[2025-05-05T13:37:06.098+0000] {taskinstance.py:1937} ERROR - Task failed with exception
Traceback (most recent call last):
  File "/home/airflow/.local/lib/python3.10/site-packages/airflow/operators/python.py", line 192, in execute
    return_value = self.execute_callable()
  File "/home/airflow/.local/lib/python3.10/site-packages/airflow/operators/python.py", line 209, in execute_callable
    return self.python_callable(*self.op_args, **self.op_kwargs)
  File "/opt/airflow/dags/Train_Data.py", line 55, in entrenar_modelo
    X_train, X_test, y_train, y_test = train_test_split(X, y, test_size=0.2, random_state=42)
  File "/home/airflow/.local/lib/python3.10/site-packages/sklearn/utils/_param_validation.py", line 216, in wrapper
    return func(*args, **kwargs)
  File "/home/airflow/.local/lib/python3.10/site-packages/sklearn/model_selection/_split.py", line 2851, in train_test_split
    n_train, n_test = _validate_shuffle_split(
  File "/home/airflow/.local/lib/python3.10/site-packages/sklearn/model_selection/_split.py", line 2481, in _validate_shuffle_split
    raise ValueError(
ValueError: With n_samples=0, test_size=0.2 and train_size=None, the resulting train set will be empty. Adjust any of the aforementioned parameters.
[2025-05-05T13:37:06.348+0000] {taskinstance.py:1400} INFO - Marking task as FAILED. dag_id=Train_Model, task_id=entrenar_modelo, execution_date=20250505T133134, start_date=20250505T133703, end_date=20250505T133706
[2025-05-05T13:37:06.405+0000] {standard_task_runner.py:104} ERROR - Failed to execute job 93 for task entrenar_modelo (With n_samples=0, test_size=0.2 and train_size=None, the resulting train set will be empty. Adjust any of the aforementioned parameters.; 114)
[2025-05-05T13:37:06.577+0000] {local_task_job_runner.py:228} INFO - Task exited with return code 1
[2025-05-05T13:37:06.754+0000] {taskinstance.py:2778} INFO - 0 downstream tasks scheduled from follow-on schedule check
